# 错误和异常
<!-- TOC -->

- [错误和异常](#错误和异常)
    - [简介](#简介)
    - [异常类](#异常类)
    - [捕获异常](#捕获异常)
        - [实现多个catch块](#实现多个catch块)
        - [在其他代码中捕获异常](#在其他代码中捕获异常)
        - [System.Exception](#systemexception)
        - [异常过滤器](#异常过滤器)
        - [重新抛出异常](#重新抛出异常)
        - [没有处理异常时发生的情况](#没有处理异常时发生的情况)
    - [用户定义的异常类](#用户定义的异常类)

<!-- /TOC -->

## 简介
- .NET framework改进了处理错误的方式。C#处理错误的机制可以为每种错误提供自定义处理方式，并把识别错误的代码和处理错误的代码分离开来。


---
## 异常类
- 在C#中，当出现某个特殊的异常错误条件时，就会创建(或抛出)一个异常对象。这个对象包含又助于跟踪问题的信息。我们可以创建自己的异常类。.NET提供了许多预定义的异常类，下面是部分类，展示了大致的模式。
```
Exception
    SystemException
        ArgumentException
            ArgumentNullException
            ArgumentOutOfRangeException
        ArithmeticException
            OverflowException
        StackOverflowException
        IOException
            FileLoadException
            FileNotFoundException
    ApplicationException
        TargetInvocationException
    CompositionException
        ChangeRejectedException
```

- 上述的所有类都在System名称空间中，但IOException和CompositionException除外。
- IOException在System.IO中，处理文件数据的读写。
- CompositionException在System.ComponentModel.Composition中，该名称空间处理部件和组件的动态加载。

- 一般情况下，异常没有特定的名称空间，异常类应放在生成异常的类所在的名称空间中。

- 对于.NET类，一般的异常类System.Exception派生自System.Object，通常不在代码中抛出该泛型对象，因为它们无法确定错误情况的本质。

- 在该层次结构中有两个重要的类：
    - SystemException——该类用于通常由.NET运行库抛出的异常。例如，栈已满会抛出StackOverflowException。调用参数不正确可以抛出ArgumentException或子类异常。
        - SystemException异常的子类包括表示致命错误和非致命错误的异常。

    - ApplicationException——在`.NET Framework`最初的设计中，时打算把这个类作为自定义应用程序异常类的基类的。不过CLR抛出的一些异常类也派生自这个类。应用程序抛出的异常则派生自SystemExcpetion。所以现在基本不从这里派生了，都是直接从Exception派生。


---
## 捕获异常
- 为了在C#中处理可能的错误情况，一般要把程序的相关部分分为3中不同的类型：
    - try块包含的代码组成了程序的正常操作部分，但这部分程序可能遇到某些严重的错误。
    - catch块包含的代码处理各种错误情况。
    - finally包含的代码清理资源或其他末尾操作。即使在try和catch中return了，finally也会执行。

- 如果检测到一个错误，代码就抛出一个异常。实例化一个异常对象类，并抛出这个异常：
```
throw new OverflowException();
```

- 只要在try中遇到一条throw语句，就会立即查找这个try对应的catch块。程序查找的catch块应表示同一个类或基类中匹配的异常类实例。


### 实现多个catch块
- 多个catch块的顺序有讲究，子类一定要放在父类前面，不然错误就会被父类先捕获。


### 在其他代码中捕获异常
- 库中的代码很少捕获异常，而是由客户端代码来决定如何处理异常。

### System.Exception
- Exception有以下属性：
    - Data 给异常添加键值语句，提供额外信息
    - HelpLink 连接到一个帮助文件上
    - InnerException 如果此异常是在catch块中抛出的，它就会包含把代码发送到catch中的异常对象
    - Message 错误文本
    - Source 导致异常的程序名或对象名
    - StackTrace 栈轨迹

- 这些属性中，StackTrace由运行库提供。Source自动填充，其他属性必须在抛出异常的代码中填充。

### 异常过滤器

- C#6 的新特性是异常过滤器。捕获不同的异常类型是，可以有行为不同的catch块。

- C#中catch语句可以使用when关键字过滤。
```
static void ExceptionFilter()
        {
            try
            {
                ThrowWithErrorErrorCode(405);
            }
            catch(MyException ex) when(ex.Code != 405)
            {
                Debug.WriteLine("code isn't 405");

            }
            catch (MyException ex)
            {
                Debug.WriteLine("code is 405");
            }
        }
        public static void ThrowWithErrorErrorCode(int code)
        {
            throw new MyException("error") { Code = code };
        }
        private class MyException : Exception
        {
            public int Code { get; set; }
            public MyException(string msg) : base(msg) { }
        }
```

### 重新抛出异常
- 捕获异常时，重新抛出异常也是非常普遍的。再次抛出异常时，可以改变异常的类型。还可以记录异常信息。

- 重新抛出异常的问题是，调用程序往往需要通过以前的异常找出其发生的原因和地点，根据异常的抛出方式，堆栈跟踪信息可能会丢失。

- 重新抛出异常时最好把旧的异常放到新异常的InnerException中。

- 下面我们看两个例子：

1. 只是重新抛出异常：
```
 static void ThrowAgain()
{
    try
    {
        JustThrowAgain();
        //ChangeThrowException();
    }
    catch(Exception ex)
    {
        Debug.WriteLine(ex.Message);
        Debug.WriteLine(ex.StackTrace);
        if(ex.InnerException!= null)
        {
            Debug.WriteLine("inner: "+ex.InnerException.Message);
            Debug.WriteLine("inner: "+ex.InnerException.StackTrace);
        }
    }
}
static void JustThrowAgain()
{
    try
    {
        ThrowMyException("test 1");
    }
    catch(Exception ex)
    {
        throw ex;
    }
}
static void ThrowMyException(string msg)
{
    throw new MyException(msg);
}
//输出
test 1

   在 C14_Exception.ExceptionDemo.ExceptionExample.JustThrowAgain() 位置 ExceptionExample.cs:行号 71
   在 C14_Exception.ExceptionDemo.ExceptionExample.ThrowAgain() 位置 ExceptionExample.cs:行号 37
```

- 可以看到，堆栈信息里只有两个函数的位置，而最原始的ThrowMyException的堆栈信息丢失了。

2. 改变原来的异常重新抛出，创建一个新的异常，把旧的异常放到InnerException中。
```
//其他代码省略
ChangeThrowException();
//...

static void ChangeThrowException()
{
    try
    {
        ThrowMyException("test 2");
    }
    catch(Exception ex)
    {
        Debug.WriteLine($"ex : {ex.Message}");
        throw new AnotherException("throw with inner", ex);
    }
}
//
throw with inner
   在 C14_Exception.ExceptionDemo.ExceptionExample.ChangeThrowException() 行号 60
   在 C14_Exception.ExceptionDemo.ExceptionExample.ThrowAgain() 行号 38
inner: test 2
inner:    在 C14_Exception.ExceptionDemo.ExceptionExample.ThrowMyException(String msg) 行号 76
   在 C14_Exception.ExceptionDemo.ExceptionExample.ChangeThrowException() 行号 55
```

- 可以看到，这次ThrowMyException的原始堆栈信息没有丢失，而是保留在了InnerException中。


3. 重新抛出异常
- 如果不应该改变异常的类型，就可以使用throw语句重新抛出相同的异常。使用throw但不传递异常对象，会抛出catch块当前异常，并保存异常信息：
```
static void NotChangeException()
{
    try
    {
        ThrowMyException("test 3");
    }
    catch (Exception ex)
    {
        throw;
    }
}
//
test 3
   在 C14_Exception.ExceptionDemo.ExceptionExample.ThrowMyException(String msg)行号 89
   在 C14_Exception.ExceptionDemo.ExceptionExample.NotChangeException()行号 72
   在 C14_Exception.ExceptionDemo.ExceptionExample.ThrowAgain() 行号 39
```

- 可以看到，这次的堆栈信息也没有丢失。

4. 使用过滤器添加功能
- 使用throw语句重新抛出异常时，调用堆栈包含抛出的地址。使用异常过滤器，可以根本不改变调用堆栈。现在添加when关键字，传递过滤器方法。这个过滤器方法记录消息，且总是返回false，因此catch块不会调用，所以异常会传递到上一层的方法中。
```
 try
{
    ThrowByFilter();
}
catch(Exception ex)
{
    Debug.WriteLine(ex.Message);
    Debug.WriteLine(ex.StackTrace);
}
static void ThrowByFilter()
{
    try
    {
        ThrowMyException("test 4");
    }
    catch(Exception ex) when (Filter(ex))
    {
        Debug.WriteLine("Never invoked");
    }

}
static bool Filter(Exception ex)
{
    Debug.WriteLine(ex.Message);
    return false;
}
//
test 4
test 4
   在 C14_Exception.ExceptionDemo.ExceptionExample.ThrowMyException(String msg)行号 107
   在 C14_Exception.ExceptionDemo.ExceptionExample.ThrowByFilter() 行号 57
   在 C14_Exception.ExceptionDemo.ExceptionExample.ThrowAgain() 行号 40
```
- 可以看到，堆栈信息没丢失。

- 异常过滤器的主要用法是基于值异常的过滤异常。异常过滤器也可以用于其他效果，比如写入日志信息，但不改变调用堆栈。然而，异常过滤器应该运行很快，所以应该只做简单的检查。

### 没有处理异常时发生的情况
- 假如代码中没有catch块处理异常。`.NET` 运行库会捕获它。实际上，`.NET`运行库把整个程序放在另一个更大的try块中，这个try块有一个catch处理程序，可以捕获任何异常。
- 捕获后代码的执行会立即终止，并给用户显示一个对话框。

---
## 用户定义的异常类
- p386